<?xml version="1.0" ?>
<!-- =================================================================================== -->
<!-- |    This document was autogenerated by xacro from my_robot.urdf.xacro            | -->
<!-- |    EDITING THIS FILE BY HAND IS NOT RECOMMENDED                                 | -->
<!-- =================================================================================== -->
  <robot name="my_robot">
    <material name="green">
      <color rgba="0 0.5 0 1"/>
    </material>
    <material name="grey">
      <color rgba="0.5 0.5 0.5 1"/>
    </material>
    <material name="orange">
      <color rgba="1.0 0.64 0.28 1"/>
    </material>
    <material name="yellow">
      <color rgba="1.0 1.0 0 1"/>
    </material>
    <link name="base_footprint">
      <visual>
        <origin rpy="0 0 0" xyz="0 0 0"/>
      </visual>
    </link>
    <link name="base_link">
      <visual>
        <geometry>
          <box size="0.6 0.4 0.2"/>
        </geometry>
        <origin rpy="0 0 0" xyz="0 0 0.1"/>
        <material name="green"/>
      </visual>
      <collision>
        <geometry>
          <box size="0.6 0.4 0.2"/>
        </geometry>
        <origin rpy="0 0 0" xyz="0 0 0.1"/>
      </collision>
      <inertial>
        <mass value="5.0"/>
        <origin rpy="0 0 0" xyz="0 0 0.1"/>
        <inertia ixx="0.6666666666666667" ixy="0" ixz="0" iyy="0.8666666666666667" iyz="0" izz="0.3333333333333334"/>
      </inertial>
    </link>
    <link name="right_wheel_link">
      <visual>
        <geometry>
          <cylinder length="0.05" radius="0.1"/>
        </geometry>
        <origin rpy="1.5707963267948966 0 0" xyz="0 0 0"/>
        <material name="grey"/>
      </visual>
      <collision>
        <geometry>
          <cylinder length="0.05" radius="0.1"/>
        </geometry>
        <origin rpy="1.5707963267948966 0 0" xyz="0 0 0"/>
      </collision>
      <inertial>
        <mass value="1.0"/>
        <origin rpy="1.5707963267948966 0 0" xyz="0 0 0"/>
        <inertia ixx="0.010833333333333335" ixy="0" ixz="0" iyy="0.010833333333333335" iyz="0" izz="0.020000000000000004"/>
      </inertial>
    </link>
    <link name="left_wheel_link">
      <visual>
        <geometry>
          <cylinder length="0.05" radius="0.1"/>
        </geometry>
        <origin rpy="1.5707963267948966 0 0" xyz="0 0 0"/>
        <material name="grey"/>
      </visual>
      <collision>
        <geometry>
          <cylinder length="0.05" radius="0.1"/>
        </geometry>
        <origin rpy="1.5707963267948966 0 0" xyz="0 0 0"/>
      </collision>
      <inertial>
        <mass value="1.0"/>
        <origin rpy="1.5707963267948966 0 0" xyz="0 0 0"/>
        <inertia ixx="0.010833333333333335" ixy="0" ixz="0" iyy="0.010833333333333335" iyz="0" izz="0.020000000000000004"/>
      </inertial>
    </link>
    <link name="caster_wheel_link">
      <visual>
        <geometry>
          <sphere radius="0.05"/>
        </geometry>
        <origin rpy="0 0 0" xyz="0 0 0"/>
        <material name="grey"/>
      </visual>
      <collision>
        <geometry>
          <sphere radius="0.05"/>
        </geometry>
        <origin rpy="0 0 0" xyz="0 0 0"/>
      </collision>
      <inertial>
        <mass value="0.5"/>
        <origin rpy="0 0 0" xyz="0 0 0"/>
        <inertia ixx="0.0020000000000000005" ixy="0" ixz="0" iyy="0.0020000000000000005" iyz="0" izz="0.0020000000000000005"/>
      </inertial>
    </link>
    <joint name="base_joint" type="fixed">
      <parent link="base_footprint"/>
      <child link="base_link"/>
      <origin rpy="0 0 0" xyz="0 0 0.1"/>
    </joint>
    <joint name="base_right_wheel_joint" type="continuous">
      <parent link="base_link"/>
      <child link="right_wheel_link"/>
      <origin rpy="0 0 0" xyz="-0.15 -0.225 0"/>
      <axis xyz="0 1 0"/>
    </joint>
    <joint name="base_left_wheel_joint" type="continuous">
      <parent link="base_link"/>
      <child link="left_wheel_link"/>
      <origin rpy="0 0 0" xyz="-0.15 0.225 0"/>
      <axis xyz="0 1 0"/>
    </joint>
    <joint name="base_caster_wheel_joint" type="fixed">
      <parent link="base_link"/>
      <child link="caster_wheel_link"/>
      <origin rpy="0 0 0" xyz="0.19999999999999998 0 -0.05"/>
    </joint>
    <gazebo reference="base_link">
      <material>Gazebo/Blue</material>
    </gazebo>
    <gazebo reference="right_wheel_link">
      <material>Gazebo/Grey</material>
    </gazebo>
    <gazebo reference="left_wheel_link">
      <material>Gazebo/Grey</material>
    </gazebo>
    <gazebo reference="caster_wheel_link">
      <material>Gazebo/Grey</material>
      <mu1 value="0.1"/>
      <mu2 value="0.2"/>
    </gazebo>
    <gazebo>
      <plugin filename="gz-sim-diff-drive-system" name="gz::sim::systems::DiffDrive">
        <left_joint>base_left_wheel_joint</left_joint>
        <right_joint>base_right_wheel_joint</right_joint>
        <frame_id>odom</frame_id>
        <odom_topic>odom</odom_topic>
        <child_frame_id>base_footprint</child_frame_id>
        <wheel_separation>0.45</wheel_separation>
        <wheel_radius>0.1</wheel_radius>
        <odom_publish_frequency>1</odom_publish_frequency>
        <topic>cmd_vel</topic>
        <max_linear_acceleration>0.033</max_linear_acceleration>
      </plugin>
    </gazebo>
  </robot>
